<?xml version="1.0" ?>
<!-- =================================================================================== -->
<!-- |    This document was autogenerated by xacro from /home/robot/catkin_ws/src/urdf_tutorial/urdf/feetecharm.urdf.xacro | -->
<!-- |    EDITING THIS FILE BY HAND IS NOT RECOMMENDED                                 | -->
<!-- =================================================================================== -->
<robot name="feetech">
    <material name="blue">
        <color rgba="0 0 0.8 1" />
    </material>
    <link name="base_link">
        <visual>
            <origin rpy="0 0 3.14" xyz="0 0 0.25" />
            <geometry>
                <box size="0.03 0.03 0.5" />
            </geometry>
            <material name="blue">
                <color rgba="0 0 1 1" />
            </material>
        </visual>
        <collision>
            <geometry>
                <box size="0.03 0.03 0.5" />
            </geometry>
        </collision>
        <inertial>
            <mass value="0.1" />
            <origin xyz="0 0 0" rpy="0 0 0" />
            <inertia ixx="0.3" iyy="0.3" izz="0.3" ixy="0.0" ixz="0.0" iyz="0.0" />
            <gravity_mode>false</gravity_mode> 
        </inertial>
    </link>
    <link name="world" />
    <joint name="world_joint" type="fixed">
        <origin rpy="0 0 0" xyz="0 0 1" />
        <!-- Place the robot wherever you want -->
        <parent link="world" />
        <child link="base_link" />
        <!-- replace this name with your robot's base link -->
    </joint>
    <link name="servo_0">
        <visual>
            <geometry>
                <mesh filename="package://urdf_tutorial/meshes/joint_2_1.stl" />
            </geometry>
        </visual>
        <collision>
            <geometry>
                <mesh filename="package://urdf_tutorial/meshes/joint_2_1.stl" />
            </geometry>
        </collision>
        <inertial>
            <mass value="0.1" />
            <origin xyz="0 0 0" rpy="0 0 0" />
            <inertia ixx="0.3" iyy="0.3" izz="0.3" ixy="0.0" ixz="0.0" iyz="0.0" />
            <gravity_mode>false</gravity_mode> 
        </inertial>
    </link>
    <joint name="joint_0" type="revolute">
        <safety_controller k_position="100.0" k_velocity="40.0" soft_lower_limit="-1.25" soft_upper_limit="1.25" />
        <axis xyz="0 0 1" />
        <parent link="base_link" />
        <child link="servo_0" />
        <origin rpy="0 0 0" xyz="0.1 0 0.35" />
        <!--change xyz for the arm location -->
        <limit effort="100000" lower="-1.57" upper="1.57" velocity="1" />
        <dynamics damping="1.0" friction="0.0"/>
    </joint>
    <link name="servo_1">
        <visual>
            <geometry>
                <mesh filename="package://urdf_tutorial/meshes/joint_3_2.stl" />
            </geometry>
            <material name="blue" />
        </visual>
        <collision>
            <geometry>
                <mesh filename="package://urdf_tutorial/meshes/joint_3_2.stl" />
            </geometry>
        </collision>
        <inertial>
            <mass value="0.1" />
            <origin xyz="0 0 0" rpy="0 0 0" />
            <inertia ixx="0.3" iyy="0.3" izz="0.3" ixy="0.0" ixz="0.0" iyz="0.0" />
            <gravity_mode>false</gravity_mode> 
        </inertial>
    </link>
    <joint name="joint_1" type="revolute">
        <safety_controller k_position="100.0" k_velocity="40.0" soft_lower_limit="-1.3" soft_upper_limit="1.9" />
        <axis xyz="0 -1 0" />
        <parent link="servo_0" />
        <child link="servo_1" />
        <origin rpy="0 0 0" xyz="0.056 0 0.0325" />
        <limit effort="100000" lower="-1.35" upper="1.57" velocity="1" />
        <dynamics damping="1.0" friction="0.0"/>
    </joint>
    <link name="servo_2">
        <visual>
            <geometry>
                <mesh filename="package://urdf_tutorial/meshes/joint_4_3.stl" />
            </geometry>
        </visual>
        <collision>
            <geometry>
                <mesh filename="package://urdf_tutorial/meshes/joint_4_3.stl" />
            </geometry>
        </collision>
        <inertial>
            <mass value="0.1" />
            <origin xyz="0 0 0" rpy="0 0 0" />
            <inertia ixx="0.3" iyy="0.3" izz="0.3" ixy="0.0" ixz="0.0" iyz="0.0" />
            <gravity_mode>false</gravity_mode> 
        </inertial>
    </link>
    <joint name="joint_2" type="revolute">
        <safety_controller k_position="100.0" k_velocity="40.0" soft_lower_limit="-3.14" soft_upper_limit="3.14" />
        <axis xyz="1 0 0" />
        <parent link="servo_1" />
        <child link="servo_2" />
        <origin rpy="0 0 0" xyz="0.1155 0.0175 0" />
        <limit effort="100000" lower="-1.57" upper="1.57" velocity="3" />
        <dynamics damping="1.0" friction="0.0"/>
    </joint>
    <link name="servo_3">
        <visual>
            <geometry>
                <mesh filename="package://urdf_tutorial/meshes/joint_5_4.stl" />
            </geometry>
            <material name="blue" />
        </visual>
        <collision>
            <geometry>
                <mesh filename="package://urdf_tutorial/meshes/joint_5_4.stl" />
            </geometry>
        </collision>
        <inertial>
            <mass value="0.1" />
            <origin xyz="0 0 0" rpy="0 0 0" />
            <inertia ixx="0.3" iyy="0.3" izz="0.3" ixy="0.0" ixz="0.0" iyz="0.0" />
        </inertial>
    </link>
    <joint name="joint_3" type="revolute">
        <safety_controller k_position="100.0" k_velocity="40.0" soft_lower_limit="-1.55" soft_upper_limit="1.55" />
        <axis xyz="0 -1 0" />
        <parent link="servo_2" />
        <child link="servo_3" />
        <origin rpy="0 0 0" xyz="0.16911 -0.01413 -0.00487" />
        <limit effort="100" lower="-1.57" upper="1.57" velocity="3" />
    </joint>
    <link name="servo_4">
        <visual>
            <geometry>
                <mesh filename="package://urdf_tutorial/meshes/joint_6_5_new.stl" />
            </geometry>
        </visual>
        <collision>
            <geometry>
                <mesh filename="package://urdf_tutorial/meshes/joint_6_5_new.stl" />
            </geometry>
        </collision>
        <inertial>
            <mass value="0.1" />
            <origin xyz="0 0 0" rpy="0 0 0" />
            <inertia ixx="0.3" iyy="0.3" izz="0.3" ixy="0.0" ixz="0.0" iyz="0.0" />

        </inertial>
    </link>
    <joint name="joint_4" type="revolute">
        <safety_controller k_position="100.0" k_velocity="40.0" soft_lower_limit="-3.14" soft_upper_limit="3.14" />
        <axis xyz="0 0 -1" />
        <parent link="servo_3" />
        <child link="servo_4" />
        <origin rpy="0 0 -1.57" xyz="0.05118 -0.016 -0.0231" />
        <limit effort="100" lower="-2" upper="2" velocity="3" />

    </joint>
    <link name="servo_5">
        <visual>
            <geometry>
                <mesh filename="package://urdf_tutorial/meshes/joint_7_6_new.stl" />
            </geometry>
            <material name="blue" />
        </visual>
        <collision>
            <geometry>
                <mesh filename="package://urdf_tutorial/meshes/joint_7_6_new.stl" />
            </geometry>
        </collision>
        <inertial>
            <mass value="0.1" />
            <origin xyz="0 0 0" rpy="0 0 0" />
            <inertia ixx="0.3" iyy="0.3" izz="0.3" ixy="0.0" ixz="0.0" iyz="0.0" />

        </inertial>
    </link>
    <joint name="joint_5" type="revolute">
        <safety_controller k_position="100.0" k_velocity="40.0" soft_lower_limit="-2.2" soft_upper_limit="2.2" />
        <axis xyz="-1 0 0" />
        <parent link="servo_4" />
        <child link="servo_5" />
        <origin rpy="0 0 0" xyz="-0.01886 0.0 -0.2255 " />
        <limit effort="100" lower="-2.3" upper="2.3" velocity="3" />

    </joint>
    <link name="servo_6">
    	
        <visual>
            <geometry>
                <mesh filename="package://urdf_tutorial/meshes/hook_new.stl" />
            </geometry>
        </visual>
        <collision>
            <geometry>
                <mesh filename="package://urdf_tutorial/meshes/hook_new.stl" />
            </geometry>
        </collision>
        <inertial>
            <mass value="0.1" />
            <origin xyz="0 0 0" rpy="0 0 0" />
            <inertia ixx="0.3" iyy="0.3" izz="0.3" ixy="0.0" ixz="0.0" iyz="0.0" />
        </inertial>
    </link>
    <joint name="joint_6" type="revolute">
        <safety_controller k_position="100.0" k_velocity="40.0" soft_lower_limit="-3.1" soft_upper_limit="3.1" />
        <axis xyz="0 0 -1" />
        <parent link="servo_5" />
        <child link="servo_6" />
        <origin rpy="0 0 0" xyz="-0.02307 -0.012 -0.02368" />
        <limit effort="100" lower="-3.14" upper="3.14" velocity="3" />

    </joint>
 <gazebo reference="servo_0">
  <gravity>false</gravity>
</gazebo>
 <gazebo reference="servo_1">
  <gravity>false</gravity>
</gazebo>
 <gazebo reference="servo_2">
  <gravity>false</gravity>
</gazebo>
 <gazebo reference="servo_3">
  <gravity>false</gravity>
</gazebo>
 <gazebo reference="servo_4">
  <gravity>false</gravity>
</gazebo>
 <gazebo reference="servo_5">
  <gravity>false</gravity>
</gazebo>
 <gazebo reference="servo_6">
  <gravity>false</gravity>
</gazebo>
    <transmission name="trans_joint_0">
        <type>transmission_interface/SimpleTransmission</type>
        <joint name="joint_0">
            <hardwareInterface>hardware_interface/EffortJointInterface</hardwareInterface>
        </joint>
        <actuator name="joint_0_motor">
            <hardwareInterface>hardware_interface/EffortJointInterface</hardwareInterface>
            <mechanicalReduction>1</mechanicalReduction>
        </actuator>
    </transmission>
    <transmission name="trans_joint_1">
        <type>transmission_interface/SimpleTransmission</type>
        <joint name="joint_1">
            <hardwareInterface>hardware_interface/EffortJointInterface</hardwareInterface>
        </joint>
        <actuator name="joint_1_motor">
            <hardwareInterface>hardware_interface/EffortJointInterface</hardwareInterface>
            <mechanicalReduction>1</mechanicalReduction>
        </actuator>
    </transmission>
    <transmission name="trans_joint_2">
        <type>transmission_interface/SimpleTransmission</type>
        <joint name="joint_2">
            <hardwareInterface>hardware_interface/EffortJointInterface</hardwareInterface>
        </joint>
        <actuator name="joint_2_motor">
            <hardwareInterface>hardware_interface/EffortJointInterface</hardwareInterface>
            <mechanicalReduction>1</mechanicalReduction>
        </actuator>
    </transmission>
    <transmission name="trans_joint_3">
        <type>transmission_interface/SimpleTransmission</type>
        <joint name="joint_3">
            <hardwareInterface>hardware_interface/EffortJointInterface</hardwareInterface>
        </joint>
        <actuator name="joint_3_motor">
            <hardwareInterface>hardware_interface/EffortJointInterface</hardwareInterface>
            <mechanicalReduction>1</mechanicalReduction>
        </actuator>
    </transmission>
    <transmission name="trans_joint_4">
        <type>transmission_interface/SimpleTransmission</type>
        <joint name="joint_4">
            <hardwareInterface>hardware_interface/EffortJointInterface</hardwareInterface>
        </joint>
        <actuator name="joint_4_motor">
            <hardwareInterface>hardware_interface/EffortJointInterface</hardwareInterface>
            <mechanicalReduction>1</mechanicalReduction>
        </actuator>
    </transmission>
    <transmission name="trans_joint_5">
        <type>transmission_interface/SimpleTransmission</type>
        <joint name="joint_5">
            <hardwareInterface>hardware_interface/EffortJointInterface</hardwareInterface>
        </joint>
        <actuator name="joint_5_motor">
            <hardwareInterface>hardware_interface/EffortJointInterface</hardwareInterface>
            <mechanicalReduction>1</mechanicalReduction>
        </actuator>
    </transmission>
    <transmission name="trans_joint_6">
        <type>transmission_interface/SimpleTransmission</type>
        <joint name="joint_6">
            <hardwareInterface>hardware_interface/EffortJointInterface</hardwareInterface>
        </joint>
        <actuator name="joint_6_motor">
            <hardwareInterface>hardware_interface/EffortJointInterface</hardwareInterface>
            <mechanicalReduction>1</mechanicalReduction>
        </actuator>
    </transmission>
    <gazebo>
        <plugin name="gazebo_ros_control" filename="libgazebo_ros_control.so">
            <robotNamespace>/</robotNamespace>
        </plugin>

    </gazebo>
</robot>

